Workbook

Sheet IDEAS
A1: Index | B1: Idea | C1: Created?
A2: 1 | B2: Doughweaving - it's like a spell that lets you summon shitty bread? Maybe the better your cooking the better bread you make?
A3: 2
A4: 3
A5: 4
A6: 5
A7: 6
A8: 7
A9: 8
A10: 9
A11: 10
A12: 11
A13: 12
A14: 13
... A51: 50

Sheet Suits EVOLVED
B1: ♥ Hearts | C1: ♣ Clubs | D1: ◆ Diamonds | E1: ♠ Spades
A2: Suit | B2: ♥ Hearts | C2: ♣ Clubs | D2: ◆ Diamonds | E2: ♠ Spades
A3: Tarot Suit | B3: Cups | C3: Wands / Batons / Rods | D3: Coins / Pentacles | E3: Swords
A4: Playing Card Class | B4: Clergy / Church | C4: Peasants / Laborers | D4: Merchants / Traders | E4: Nobility / Military
A5: Season | B5: Spring | C5: Summer | D5: Autumn | E5: Winter
A6: Element (Game) | B6: Brilliant | C6: Fire | D6: Shadow | E6: Frost
A7: Classical Element | B7: Water | C7: Fire | D7: Earth | E7: Air
A8: Temperament | B8: Phlegmatic (calm, empathetic, patient, sustaining) | C8: Choleric (passionate, energetic, quick to act, ambitious) | D8: Melancholic (analytical, precise, methodical, detail-focused) | E8: Sanguine (communicative, intellectual, quick, curious)
A9: Alchemical Principle | B9: Mercury (mediation, the dissolving agent, what flows between) | C9: Sulfur (active spirit, transformative fire, the essence of a thing) | D9: Salt (stable form, material body, what persists and crystallizes) | E9: Mercury (swift messenger, catalyst, the intellect that perceives connections)
A10: Jungian Function | B10: Feeling (value judgment; what matters and why) | C10: Intuition (perception of possibilities; seeing what could be) | D10: Sensation (direct perception; trusting what can be measured) | E10: Thinking (logical analysis; judgment by principle)
A11: Astrology | B11: Cancer · Scorpio · Pisces (protective, deep, boundaryless) | C11: Aries · Leo · Sagittarius (pioneering, radiant, questing) | D11: Taurus · Virgo · Capricorn (patient, precise, disciplined) | E11: Gemini · Libra · Aquarius (communicative, balanced, principled)
A12: Symbolic Images | B12: Chalice, cauldron, well, mirror, the moon, rain, tears, the tide | C12: Torch, forge, staff, lance, the noon sun, bonfire, the phoenix, the serpent | D12: Coin, gem, loom, scales, the labyrinth, talisman, mason's tools, the plowed field | E12: Sword, scalpel, pen/quill, scales of justice, compass, the bare winter tree
A13: Mythic Parallels | B13: The Fisher King, Avalon, the Lady of the Lake, Aphrodite, the Holy Grail | C13: Prometheus, Heracles, Hephaestus, the Phoenix, Shiva's dance | D13: Daedalus, Anansi, Loki (creative aspect), the Philosopher's Stone | E13: Athena, Sherlock Holmes, Themis/Lady Justice, the Angel of Eden
... A20: Suit Effect (Social) | B20: Lasting outcome; target genuinely believes | C20: Pressured outcome; target backs down | D20: Information / angle; target's position weakened | E20: Controlled outcome; you set the terms

Sheet Costs
A1: Item | B1: Average* Cost | C1: Notes
A2: One-handed weapons | B2: 3
A3: Two-handed weapons | B3: 6
A4: Thrown weapons | B4: 5 | C4: Generally sold as a unit, enough to not need to keep track of
A5: Light armor | B5: 4
A6: Heavy armor | B6: 8
A7: Basic clothing/jewelry | B7: 3
A8: Bag / backpack | B8: 3 x "tier" | C8: Knapsack, Backpack, Rucksack, etc.
A9: Medicinal supply | B9: 2
A10: Skill kit | B10: 5
A11: Alchemical items | B11: 2 x Level
A12: Masterwork items | B12: 20 x Level

Sheet Crafting Table
A1: Item Name | B1: Level | C1: Type | D1: Base Item | E1: Base Mat A | F1: Base Mat B | G1: Opt Mat A | H1: Opt Mat B | I1: Duration | J1: In Use?
A2: Power Snack | B2: Level 1 | C2: Food | E2: Food | G2: Medicinal | H2: Bone | J2: TRUE
A3: Travel Rations | B3: Level 1-5 | C3: Food | E3: Food | J3: TRUE
A4: Hearty Meal | B4: Level 2 | C4: Food | E4: Food | G4: Medicinal | H4: Bone | J4: TRUE
A5: Soul Soup | B5: Level 3 | C5: Food | E5: Food | G5: Medicinal | H5: Bone | J5: TRUE
A6: Muscular Feast | B6: Level 4 | C6: Food | E6: Food | G6: Medicinal | H6: Bone | J6: TRUE
A7: Trancendental Entree | B7: Level 5 | C7: Food | E7: Food | G7: Medicinal | H7: Bone | J7: TRUE
A8: Acidic Flask | B8: Level 1 | C8: Grenade | E8: [Elemental] | G8: Medicinal | J8: TRUE
A9: Immaculate Adhesive | B9: Level 1 | C9: Grenade | E9: Bone | G9: Medicinal | J9: TRUE
A10: Bottled Fire | B10: Level 2 | C10: Grenade | E10: Fire | G10: Medicinal | J10: TRUE
A11: Smokejar | B11: Level 2 | C11: Grenade | E11: Fire | G11: Medicinal | J11: TRUE
A12: Bonemelter | B12: Level 3 | C12: Grenade | E12: Shadow | G12: Medicinal | J12: TRUE
A13: Snowstorm | B13: Level 3 | C13: Grenade | E13: Frost | G13: Medicinal | J13: TRUE
A14: Sunbeam | B14: Level 4 | C14: Grenade | E14: Brilliant | G14: Medicinal | J14: TRUE
A15: Hellfire Bomb | B15: Level 4 | C15: Grenade | E15: Fire | G15: Medicinal | J15: TRUE
A16: Thunderclap-in-a-jar | B16: Level 5 | C16: Grenade | E16: Fire | G16: Medicinal | J16: TRUE
A17: Basic Poison | B17: Level 1-5 | C17: Poison | E17: Medicinal | I17: Instant | J17: TRUE
A18: Energizing Brew | B18: Level 1 | C18: Potion | G18: Medicinal | I18: Hour | J18: TRUE
A19: Fortifying Concoction | B19: Level 1 | C19: Potion | E19: Bone | G19: Medicinal | I19: Instant | J19: TRUE
A20: Elemental-Attuned Tincture | B20: Level 2 | C20: Potion | E20: [Elemental] | G20: Medicinal | I20: Hour | J20: TRUE
A21: Essential Ointment | B21: Level 2 | C21: Potion | E21: Brilliant | G21: Medicinal | I21: Instant | J21: TRUE
A22: Soldier's Salts | B22: Level 2 | C22: Potion | E22: Brilliant | G22: Medicinal | I22: Instant | J22: TRUE
A23: Calming Brew | B23: Level 3 | C23: Potion | E23: Frost | G23: Medicinal | I23: Instant | J23: TRUE
A24: Healing Potion | B24: Level 3 | C24: Potion | E24: Bone | G24: Medicinal | I24: Instant | J24: TRUE
A25: Liquid Charisma | B25: Level 3 | C25: Potion | E25: Precious | G25: Medicinal | I25: Hour | J25: TRUE
A26: Earthen Draught | B26: Level 4 | C26: Potion | E26: Bone | G26: Medicinal | I26: Hour | J26: TRUE
A27: Fighter's Friend | B27: Level 4 | C27: Potion | E27: Brilliant | G27: Medicinal | I27: Instant | J27: TRUE
A28: Swiftblade Vial | B28: Level 4 | C28: Potion | E28: Fire | G28: Medicinal | I28: Instant | J28: TRUE
A29: Insanity Potion | B29: Level 5 | C29: Potion | E29: Bone | G29: Medicinal | I29: Hour | J29: TRUE
A30: Cobblestone Boots | B30: Level 1 | C30: Feet | D30: Clothing | E30: Metal
A31: Lightfoot Shoes | B31: Level 1-5 | C31: Feet | D31: Clothing | E31: Fire
A32: Feathered Sandals | B32: Level 1 | C32: Feet | D32: Clothing | E32: Wood
A33: Slipstream Sandals | B33: Level 2 | C33: Feet | D33: Clothing | E33: Shadow
A34: Vaulting Boots | B34: Level 3 | C34: Feet | D34: Clothing | E34: Wood
A35: Greaves of the Stalwart Guardian | B35: Level 5 | C35: Feet | D35: Clothing | E35: Metal | F35: Bone
A36: Armory Gauntlets | B36: Level 1 | C36: Hands | D36: Clothing | E36: (Bone/Metal/Wood)
A37: Deft Gloves | B37: Level 2 | C37: Hands | D37: Clothing | E37: Metal | F37: Precious
A38: Mighty Mitts | B38: Level 3 | C38: Hands | D38: Clothing | E38: Fire | F38: Brilliant
A39: Confident Cap | B39: Level 3 | C39: Head | D39: Clothing | E39: Precious | J39: TRUE
A40: Mask of Night | B40: Level 1 | C40: Head | D40: Clothing | E40: Shadow
...

Sheet HExboys
A1: Distance per Hex | B1: 1 | C1: km?
A2: Distance per move | B2: 0.25
A4: Terrain | B4: Speed Mod | C4: Moves to Travel
A5: Plains | B5: 1 | C5: =$B$1/$B$2/B5 -> 4
A6: Forest / Swamp / Hills | B6: 0.5 | C6: =$B$1/$B$2/B6 -> 8
A7: Plains /w road | B7: 2 | C7: =$B$1/$B$2/B7 -> 2
A8: Forest / Swamp / Hills /w road | B8: 1 | C8: =$B$1/$B$2/B8 -> 4
A11: Distance traveled per day, top end | B11: 20 | C11: mi
A12: Distance but in kilometers | B12: =B11*5/3 -> 33.333333 | C12: km
A13: Turns per day | B13: 16
A14: Moves per turn | B14: 4
A15: Moves per day | B15: =B14*B13 -> 64
A16: Average moves per km | B16: =B15/B12 -> 1.92
B18: km | C18: km/move
A19: Travel across easy road per turn | B19: 2 | C19: =B19/4 -> 0.5
A20: Travel across gentle plains | B20: 1 | C20: =B20/4 -> 0.25
A21: Travel across rough terrain with road | B21: 1 | C21: =B21/4 -> 0.25
A22: Travel across rough terrain | B22: 0.5 | C22: =B22/4 -> 0.125

Sheet DM Guide
A1: Gold per character per tier: | B1: =4 + 1/3 -> 4.3333333
A3: Starting XP | B3: 75
A4: Ending XP | B4: 200
A5: Sessions | B5: 12
A7: XP to gain | B7: =B4-B3 -> 125
A8: XP per session | B8: =ROUND(B7/B5,0) -> 10
A9: Starting XP/session | B9: =ROUND(B8 * 2/3,0) -> 7
A10: Ending XP/session | B10: =ROUND(B8 * 4/3,0) -> 13

Sheet BALANCE
A1: Values | H1: ='THE TABEL'!C2 -> 1 | I1: ='THE TABEL'!D2 -> 1 | J1: ='THE TABEL'!E2 -> 2 | K1: ='THE TABEL'!F2 -> 3.0512821 | L1: ='THE TABEL'!G2 -> 4 | M1: ='THE TABEL'!H2 -> 3 | N1: ='THE TABEL'!I2 -> 1 | O1: ='THE TABEL'!J2 -> 1.5 | ... AE1: ='THE TABEL'!Z2
A2: Name | B2: Type | C2: Level | D2: Net | E2: Value | F2: Rate of Use / Encounter | G2: Target | H2: ='THE TABEL'!C1 -> Fudge Value | I2: ='THE TABEL'!D1 -> Acc / Def 💯 | J2: ='THE TABEL'!E1 -> Damage | K2: ='THE TABEL'!F1 -> Card 💯 | L2: ='THE TABEL'!G1 -> Health 💯 | M2: ='THE TABEL'!H1 -> 1 AP 💯 | N2: ='THE TABEL'!I1 -> Debuff | O2: ='THE TABEL'!J1 -> Gold 💯 | ... AE2: ='THE TABEL'!Z1
A3: Brace | B3: Tech | C3: 1 | D3: =E3*F3-G3 -> 0 | E3: =SUMPRODUCT($H$1:$AF$1,H3:AF3) -> 3 | F3: 1 | G3: =C3*3 -> 3 | M3: -1 | P3: 2
A4: Soulblade | B4: Tech | C4: 1 | D4: =E4*F4-G4 -> 0 | E4: =SUMPRODUCT($H$1:$AF$1,H4:AF4) -> 3 | F4: 1 | G4: =C4*3 -> 3 | M4: 1
A5: Vow of Poverty | B5: Tech | C5: 1 | D5: =E5*F5-G5 -> 0.16666667 | E5: =SUMPRODUCT($H$1:$AF$1,H5:AF5) -> 9.5 | F5: =1/3 -> 0.33333333 | G5: =C5*3 -> 3 | H5: 20 | O5: -7
A6: Blindsight | B6: Tech | C6: 2 | D6: =E6*F6-G6 -> 0 | E6: =SUMPRODUCT($H$1:$AF$1,H6:AF6) -> 6 | F6: 1 | G6: =C6*3 -> 6 | H6: 3 | M6: 1
A7: Blood-Powered Spirit | B7: Tech | C7: 2 | D7: =E7*F7-G7 -> 1 | E7: =SUMPRODUCT($H$1:$AF$1,H7:AF7) -> 7 | F7: 1 | G7: =C7*3 -> 6 | H7: 6 | J7: 2.5 | L7: -1
A8: Bound Across Mountians | B8: Tech | C8: 2 | D8: =E8*F8-G8 -> -0.5 | E8: =SUMPRODUCT($H$1:$AF$1,H8:AF8) -> 11 | F8: 0.5 | G8: =C8*3 -> 6 | L8: 2 | M8: 1
A9: Canopy Creeper | B9: Tech | C9: 2 | D9: =E9*F9-G9 -> 0 | E9: =SUMPRODUCT($H$1:$AF$1,H9:AF9) -> 12 | F9: 0.5 | G9: =C9*3 -> 6 | H9: 6 | M9: 2
A10: Falling Tumble | B10: Tech | C10: 2 | D10: =E10*F10-G10 -> -0.5 | E10: =SUMPRODUCT($H$1:$AF$1,H10:AF10) -> 11 | F10: 0.5 | G10: =C10*3 -> 6 | L10: 2 | M10: 1
A11: Grim Resolve | B11: Tech | C11: 2 | D11: =E11*F11-G11 -> -7.8974359 | E11: =SUMPRODUCT($H$1:$AF$1,H11:AF11) -> -0.94871795 | F11: 2 | G11: =C11*3 -> 6 | K11: 1 | L11: -1
A12: One Eye Behind You | B12: Tech | C12: 2 | D12: =E12*F12-G12 -> 0 | E12: =SUMPRODUCT($H$1:$AF$1,H12:AF12) -> 6 | F12: 1 | G12: =C12*3 -> 6 | M12: 2
A13: Second Wind | B13: Tech | C13: 2 | D13: =E13*F13-G13 -> 0.80615385 | E13: =SUMPRODUCT($H$1:$AF$1,H13:AF13) -> 2.2687179 | F13: 3 | G13: =C13*3 -> 6 | K13: -1 | L13: 1.33
A14: Solemn Pact | B14: Tech | C14: 2 | D14: =E14*F14-G14 -> -1 | E14: =SUMPRODUCT($H$1:$AF$1,H14:AF14) -> 5 | F14: 1 | G14: =C14*3 -> 6 | V14: 2
A15: Toughened Body | B15: Tech | C15: 2 | D15: =E15*F15-G15 -> 0 | E15: =SUMPRODUCT($H$1:$AF$1,H15:AF15) -> 12 | F15: 0.5 | G15: =C15*3 -> 6 | S15: 3
A16: Trout Seeming | B16: Tech | C16: 2 | D16: =E16*F16-G16 -> -1.75 | E16: =SUMPRODUCT($H$1:$AF$1,H16:AF16) -> 17 | F16: 0.25 | G16: =C16*3 -> 6 | M16: 4 | V16: 2
A17: Skin of Stone | B17: Tech | C17: 3 | D17: =E17*F17-G17 -> 0 | E17: =SUMPRODUCT($H$1:$AF$1,H17:AF17) -> 9 | F17: 1 | G17: =C17*3 -> 9 | M17: -1 | P17: 4
A18: Solemn Perseverance | B18: Tech | C18: 3 | D18: =E18*F18-G18 -> -1 | E18: =SUMPRODUCT($H$1:$AF$1,H18:AF18) -> 8 | F18: 1 | G18: =C18*3 -> 9 | N18: 2 | P18: 2
A19: Temper Soulblade | B19: Tech | C19: 3 | D19: =E19*F19-G19 -> 0 | E19: =SUMPRODUCT($H$1:$AF$1,H19:AF19) -> 1.5 | F19: 6 | G19: =C19*3 -> 9 | N19: 1.5
A20: Toughened Resolve | B20: Tech | C20: 3 | D20: =E20*F20-G20 -> 0 | E20: =SUMPRODUCT($H$1:$AF$1,H20:AF20) -> 18 | F20: 0.5 | G20: =C20*3 -> 9 | R20: 2 | S20: 2
A21: Lay On Hands | B21: Tech | C21: 4 | D21: =E21*F21-G21 -> 3.4423077 | E21: =SUMPRODUCT($H$1:$AF$1,H21:AF21) -> 2.5737179 | F21: 6 | G21: =C21*3 -> 12 | K21: -1 | T21: =0.5 * 1.25 -> 0.625 | U21: =0.5 * 1.25 -> 0.625
A22: Mind and Body Unbroken | B22: Tech | C22: 4 | D22: =E22*F22-G22 -> -3.525641 | E22: =SUMPRODUCT($H$1:$AF$1,H22:AF22) -> 16.948718 | F22: 0.5 | G22: =C22*3 -> 12 | K22: -1 | L22: 2 | M22: 4
A23: Strength from the Slain | B23: Tech | C23: 3 | D23: =E23*F23-G23 -> 2.25 | E23: =SUMPRODUCT($H$1:$AF$1,H23:AF23) -> 7.5 | F23: 1.5 | G23: =C23*3 -> 9 | M23: -1 | N23: 2 | P23: 2 | V23: 1
A24: Solemn Covenant | B24: Tech | C24: 4 | D24: =E24*F24-G24 -> 0 | E24: =SUMPRODUCT($H$1:$AF$1,H24:AF24) -> 12 | F24: 1 | G24: =C24*3 -> 12 | H24: 12
A25: Toughened Spirit | B25: Tech | C25: 4 | D25: =E25*F25-G25 -> 0.5 | E25: =SUMPRODUCT($H$1:$AF$1,H25:AF25) -> 25 | F25: 0.5 | G25: =C25*3 -> 12 | R25: 5
A26: Air of Mystery | B26: Tech | C26: 2 | D26: =E26*F26-G26 -> -1.75 | E26: =SUMPRODUCT($H$1:$AF$1,H26:AF26) -> 8.5 | F26: 0.5 | G26: =C26*3 -> 6 | H26: 6 | V26: 1
A27: Awaken Armament | B27: Tech | C27: 2 | D27: =E27*F27-G27 -> -7.6538462 | E27: =SUMPRODUCT($H$1:$AF$1,H27:AF27) -> -1.6538462 | F27: 1 | G27: =C27*3 -> 6 | K27: -3 | O27: 5
A28: Legerdemain | B28: Tech | C28: 2 | D28: =E28*F28-G28 -> -0.25 | E28: =SUMPRODUCT($H$1:$AF$1,H28:AF28) -> 11.5 | F28: 0.5 | G28: =C28*3 -> 6 | M28: 3 | V28: 1
A29: Patch Up | B29: Tech | C29: 2 | D29: =E29*F29-G29 -> 0.47435897 | E29: =SUMPRODUCT($H$1:$AF$1,H29:AF29) -> 12.948718 | F29: 0.5 | G29: =C29*3 -> 6 | K29: -1 | L29: 4
A30: Quick Draw | B30: Tech | C30: 2 | D30: =E30*F30-G30 -> 0 | E30: =SUMPRODUCT($H$1:$AF$1,H30:AF30) -> 6 | F30: 1 | G30: =C30*3 -> 6 | M30: 2
A31: Re-purpose Materials | B31: Tech | C31: 2 | D31: =E31*F31-G31 -> 3 | E31: =SUMPRODUCT($H$1:$AF$1,H31:AF31) -> 18 | F31: 0.5 | G31: =C31*3 -> 6 | O31: 12
A32: Scrapcraft | B32: Tech | C32: 2 | D32: =E32*F32-G32 -> 0 | E32: =SUMPRODUCT($H$1:$AF$1,H32:AF32) -> 6 | F32: 1 | G32: =C32*3 -> 6 | H32: 6
A33: Battle Maneuver 1 | B33: Tech | C33: 1 | D33: =E33*F33-G33 -> -0.25 | E33: =SUMPRODUCT($H$1:$AF$1,H33:AF33) -> 2.75 | F33: 1 | G33: =C33*3 -> 3 | M33: -2 | N33: 3.25 | W33: 1
A34: Battle Maneuver 2 | B34: Tech | C34: 2 | D34: =E34*F34-G34 -> -0.25 | E34: =SUMPRODUCT($H$1:$AF$1,H34:AF34) -> 5.75 | F34: 1 | G34: =C34*3 -> 6 | M34: -2 | N34: 6.25 | W34: 1
A35: Battle Maneuver 3 | B35: Tech | C35: 3 | D35: =E35*F35-G35 -> -0.5 | E35: =SUMPRODUCT($H$1:$AF$1,H35:AF35) -> 8.5 | F35: 1 | G35: =C35*3 -> 9 | M35: -2 | N35: 3.5 | W35: 2
A36: Battle Maneuver 4 | B36: Tech | C36: 4 | D36: =E36*F36-G36 -> -0.5 | E36: =SUMPRODUCT($H$1:$AF$1,H36:AF36) -> 11.5 | F36: 1 | G36: =C36*3 -> 12 | M36: -2 | N36: 6.5 | W36: 2
A37: Feint | B37: Tech | C37: 1 | D37: =E37*F37-G37 -> -1 | E37: =SUMPRODUCT($H$1:$AF$1,H37:AF37) -> 2 | F37: 1 | G37: =C37*3 -> 3 | I37: 2 | M37: -1 | N37: 3
A38: Magehunter | B38: Tech | C38: 1 | D38: =E38*F38-G38 -> 0 | E38: =SUMPRODUCT($H$1:$AF$1,H38:AF38) -> 3 | F38: 1 | G38: =C38*3 -> 3 | M38: 1
A39: Blinkstep | B39: Tech | C39: 2 | D39: =E39*F39-G39 -> 0 | E39: =SUMPRODUCT($H$1:$AF$1,H39:AF39) -> 6 | F39: 1 | G39: =C39*3 -> 6 | M39: 2
A40: Drifting Form | B40: Tech | C40: 2 | D40: =E40*F40-G40 -> -0.1025641 | E40: =SUMPRODUCT($H$1:$AF$1,H40:AF40) -> 2.9487179 | F40: 2 | G40: =C40*3 -> 6 | I40: 6 | K40: -1
...

Sheet THE TABEL
A1: :^) | C1: =INDEX($A:$A,COLUMN(C1)) -> Fudge Value | D1: =INDEX($A:$A,COLUMN(D1)) -> Acc / Def 💯 | E1: =INDEX($A:$A,COLUMN(E1)) -> Damage | F1: =INDEX($A:$A,COLUMN(F1)) -> Card 💯 | G1: =INDEX($A:$A,COLUMN(G1)) -> Health 💯 | H1: =INDEX($A:$A,COLUMN(H1)) -> 1 AP 💯 | I1: =INDEX($A:$A,COLUMN(I1)) -> Debuff | J1: =INDEX($A:$A,COLUMN(J1)) -> Gold 💯 | ... Z1: =INDEX($A:$A,COLUMN(Z1))
B2: VALUE | C2: =INDEX($B:$B,COLUMN(C2)) -> 1 | D2: =INDEX($B:$B,COLUMN(D2)) -> 1 | E2: =INDEX($B:$B,COLUMN(E2)) -> 2 | F2: =INDEX($B:$B,COLUMN(F2)) -> 3.0512821 | G2: =INDEX($B:$B,COLUMN(G2)) -> 4 | H2: =INDEX($B:$B,COLUMN(H2)) -> 3 | I2: =INDEX($B:$B,COLUMN(I2)) -> 1 | J2: =INDEX($B:$B,COLUMN(J2)) -> 1.5 | ... Z2: =INDEX($B:$B,COLUMN(Z2))
A3: Fudge Value | B3: 1 | C3: =IF(ISBLANK($B3),"",IFERROR($B3/C$2,"")) -> 1 | D3: =IF(ISBLANK($B3),"",IFERROR($B3/D$2,"")) -> 1 | E3: =IF(ISBLANK($B3),"",IFERROR($B3/E$2,"")) -> 0.5 | F3: =IF(ISBLANK($B3),"",IFERROR($B3/F$2,"")) -> 0.32773109 | G3: =IF(ISBLANK($B3),"",IFERROR($B3/G$2,"")) -> 0.25 | H3: =IF(ISBLANK($B3),"",IFERROR($B3/H$2,"")) -> 0.33333333 | I3: =IF(ISBLANK($B3),"",IFERROR($B3/I$2,"")) -> 1 | J3: =IF(ISBLANK($B3),"",IFERROR($B3/J$2,"")) -> 0.66666667 | ... AA3: =IF(ISBLANK($B3),"",IFERROR($B3/AA$2,""))
A4: Acc / Def 💯 | B4: 1 | C4: =IF(ISBLANK($B4),"",IFERROR($B4/C$2,"")) -> 1 | D4: =IF(ISBLANK($B4),"",IFERROR($B4/D$2,"")) -> 1 | E4: =IF(ISBLANK($B4),"",IFERROR($B4/E$2,"")) -> 0.5 | F4: =IF(ISBLANK($B4),"",IFERROR($B4/F$2,"")) -> 0.32773109 | G4: =IF(ISBLANK($B4),"",IFERROR($B4/G$2,"")) -> 0.25 | H4: =IF(ISBLANK($B4),"",IFERROR($B4/H$2,"")) -> 0.33333333 | I4: =IF(ISBLANK($B4),"",IFERROR($B4/I$2,"")) -> 1 | J4: =IF(ISBLANK($B4),"",IFERROR($B4/J$2,"")) -> 0.66666667 | ... AA4: =IF(ISBLANK($B4),"",IFERROR($B4/AA$2,""))
A5: Damage | B5: 2 | C5: =IF(ISBLANK($B5),"",IFERROR($B5/C$2,"")) -> 2 | D5: =IF(ISBLANK($B5),"",IFERROR($B5/D$2,"")) -> 2 | E5: =IF(ISBLANK($B5),"",IFERROR($B5/E$2,"")) -> 1 | F5: =IF(ISBLANK($B5),"",IFERROR($B5/F$2,"")) -> 0.65546218 | G5: =IF(ISBLANK($B5),"",IFERROR($B5/G$2,"")) -> 0.5 | H5: =IF(ISBLANK($B5),"",IFERROR($B5/H$2,"")) -> 0.66666667 | I5: =IF(ISBLANK($B5),"",IFERROR($B5/I$2,"")) -> 2 | J5: =IF(ISBLANK($B5),"",IFERROR($B5/J$2,"")) -> 1.3333333 | ... AA5: =IF(ISBLANK($B5),"",IFERROR($B5/AA$2,""))
A6: Card 💯 | B6: 3.0512821 | C6: =IF(ISBLANK($B6),"",IFERROR($B6/C$2,"")) -> 3.0512821 | D6: =IF(ISBLANK($B6),"",IFERROR($B6/D$2,"")) -> 3.0512821 | E6: =IF(ISBLANK($B6),"",IFERROR($B6/E$2,"")) -> 1.525641 | F6: =IF(ISBLANK($B6),"",IFERROR($B6/F$2,"")) -> 1 | G6: =IF(ISBLANK($B6),"",IFERROR($B6/G$2,"")) -> 0.76282051 | H6: =IF(ISBLANK($B6),"",IFERROR($B6/H$2,"")) -> 1.017094 | I6: =IF(ISBLANK($B6),"",IFERROR($B6/I$2,"")) -> 3.0512821 | J6: =IF(ISBLANK($B6),"",IFERROR($B6/J$2,"")) -> 2.034188 | ... AA6: =IF(ISBLANK($B6),"",IFERROR($B6/AA$2,""))
A7: Health 💯 | B7: 4 | C7: =IF(ISBLANK($B7),"",IFERROR($B7/C$2,"")) -> 4 | D7: =IF(ISBLANK($B7),"",IFERROR($B7/D$2,"")) -> 4 | E7: =IF(ISBLANK($B7),"",IFERROR($B7/E$2,"")) -> 2 | F7: =IF(ISBLANK($B7),"",IFERROR($B7/F$2,"")) -> 1.3109244 | G7: =IF(ISBLANK($B7),"",IFERROR($B7/G$2,"")) -> 1 | H7: =IF(ISBLANK($B7),"",IFERROR($B7/H$2,"")) -> 1.3333333 | I7: =IF(ISBLANK($B7),"",IFERROR($B7/I$2,"")) -> 4 | J7: =IF(ISBLANK($B7),"",IFERROR($B7/J$2,"")) -> 2.6666667 | ... AA7: =IF(ISBLANK($B7),"",IFERROR($B7/AA$2,""))
A8: 1 AP 💯 | B8: 3 | C8: =IF(ISBLANK($B8),"",IFERROR($B8/C$2,"")) -> 3 | D8: =IF(ISBLANK($B8),"",IFERROR($B8/D$2,"")) -> 3 | E8: =IF(ISBLANK($B8),"",IFERROR($B8/E$2,"")) -> 1.5 | F8: =IF(ISBLANK($B8),"",IFERROR($B8/F$2,"")) -> 0.98319328 | G8: =IF(ISBLANK($B8),"",IFERROR($B8/G$2,"")) -> 0.75 | H8: =IF(ISBLANK($B8),"",IFERROR($B8/H$2,"")) -> 1 | I8: =IF(ISBLANK($B8),"",IFERROR($B8/I$2,"")) -> 3 | J8: =IF(ISBLANK($B8),"",IFERROR($B8/J$2,"")) -> 2 | ... AA8: =IF(ISBLANK($B8),"",IFERROR($B8/AA$2,""))
A9: Debuff | B9: 1 | C9: =IF(ISBLANK($B9),"",IFERROR($B9/C$2,"")) -> 1 | D9: =IF(ISBLANK($B9),"",IFERROR($B9/D$2,"")) -> 1 | E9: =IF(ISBLANK($B9),"",IFERROR($B9/E$2,"")) -> 0.5 | F9: =IF(ISBLANK($B9),"",IFERROR($B9/F$2,"")) -> 0.32773109 | G9: =IF(ISBLANK($B9),"",IFERROR($B9/G$2,"")) -> 0.25 | H9: =IF(ISBLANK($B9),"",IFERROR($B9/H$2,"")) -> 0.33333333 | I9: =IF(ISBLANK($B9),"",IFERROR($B9/I$2,"")) -> 1 | J9: =IF(ISBLANK($B9),"",IFERROR($B9/J$2,"")) -> 0.66666667 | ... AA9: =IF(ISBLANK($B9),"",IFERROR($B9/AA$2,""))
A10: Gold 💯 | B10: 1.5 | C10: =IF(ISBLANK($B10),"",IFERROR($B10/C$2,"")) -> 1.5 | D10: =IF(ISBLANK($B10),"",IFERROR($B10/D$2,"")) -> 1.5 | E10: =IF(ISBLANK($B10),"",IFERROR($B10/E$2,"")) -> 0.75 | F10: =IF(ISBLANK($B10),"",IFERROR($B10/F$2,"")) -> 0.49159664 | G10: =IF(ISBLANK($B10),"",IFERROR($B10/G$2,"")) -> 0.375 | H10: =IF(ISBLANK($B10),"",IFERROR($B10/H$2,"")) -> 0.5 | I10: =IF(ISBLANK($B10),"",IFERROR($B10/I$2,"")) -> 1.5 | J10: =IF(ISBLANK($B10),"",IFERROR($B10/J$2,"")) -> 1 | ... AA10: =IF(ISBLANK($B10),"",IFERROR($B10/AA$2,""))
A11: Protected 💯 | B11: =4 * 75% -> 3 | C11: =IF(ISBLANK($B11),"",IFERROR($B11/C$2,"")) -> 3 | D11: =IF(ISBLANK($B11),"",IFERROR($B11/D$2,"")) -> 3 | E11: =IF(ISBLANK($B11),"",IFERROR($B11/E$2,"")) -> 1.5 | F11: =IF(ISBLANK($B11),"",IFERROR($B11/F$2,"")) -> 0.98319328 | G11: =IF(ISBLANK($B11),"",IFERROR($B11/G$2,"")) -> 0.75 | H11: =IF(ISBLANK($B11),"",IFERROR($B11/H$2,"")) -> 1 | I11: =IF(ISBLANK($B11),"",IFERROR($B11/I$2,"")) -> 3 | J11: =IF(ISBLANK($B11),"",IFERROR($B11/J$2,"")) -> 2 | ... AA11: =IF(ISBLANK($B11),"",IFERROR($B11/AA$2,""))
A12: Sift | B12: 0.64 | C12: =IF(ISBLANK($B12),"",IFERROR($B12/C$2,"")) -> 0.64 | D12: =IF(ISBLANK($B12),"",IFERROR($B12/D$2,"")) -> 0.64 | E12: =IF(ISBLANK($B12),"",IFERROR($B12/E$2,"")) -> 0.32 | F12: =IF(ISBLANK($B12),"",IFERROR($B12/F$2,"")) -> 0.2097479 | G12: =IF(ISBLANK($B12),"",IFERROR($B12/G$2,"")) -> 0.16 | H12: =IF(ISBLANK($B12),"",IFERROR($B12/H$2,"")) -> 0.21333333 | I12: =IF(ISBLANK($B12),"",IFERROR($B12/I$2,"")) -> 0.64 | J12: =IF(ISBLANK($B12),"",IFERROR($B12/J$2,"")) -> 0.42666667 | ... AA12: =IF(ISBLANK($B12),"",IFERROR($B12/AA$2,""))
A13: Shallow HP 💯 | B13: =5 / 4 * 4 -> 5 | C13: =IF(ISBLANK($B13),"",IFERROR($B13/C$2,"")) -> 5 | D13: =IF(ISBLANK($B13),"",IFERROR($B13/D$2,"")) -> 5 | E13: =IF(ISBLANK($B13),"",IFERROR($B13/E$2,"")) -> 2.5 | F13: =IF(ISBLANK($B13),"",IFERROR($B13/F$2,"")) -> 1.6386555 | G13: =IF(ISBLANK($B13),"",IFERROR($B13/G$2,"")) -> 1.25 | H13: =IF(ISBLANK($B13),"",IFERROR($B13/H$2,"")) -> 1.6666667 | I13: =IF(ISBLANK($B13),"",IFERROR($B13/I$2,"")) -> 5 | J13: =IF(ISBLANK($B13),"",IFERROR($B13/J$2,"")) -> 3.3333333 | ... AA13: =IF(ISBLANK($B13),"",IFERROR($B13/AA$2,""))
A14: Deep HP 💯 | B14: 4 | C14: =IF(ISBLANK($B14),"",IFERROR($B14/C$2,"")) -> 4 | D14: =IF(ISBLANK($B14),"",IFERROR($B14/D$2,"")) -> 4 | E14: =IF(ISBLANK($B14),"",IFERROR($B14/E$2,"")) -> 2 | F14: =IF(ISBLANK($B14),"",IFERROR($B14/F$2,"")) -> 1.3109244 | G14: =IF(ISBLANK($B14),"",IFERROR($B14/G$2,"")) -> 1 | H14: =IF(ISBLANK($B14),"",IFERROR($B14/H$2,"")) -> 1.3333333 | I14: =IF(ISBLANK($B14),"",IFERROR($B14/I$2,"")) -> 4 | J14: =IF(ISBLANK($B14),"",IFERROR($B14/J$2,"")) -> 2.6666667 | ... AA14: =IF(ISBLANK($B14),"",IFERROR($B14/AA$2,""))
A15: Shallow Heal 💯 | B15: 4 | C15: =IF(ISBLANK($B15),"",IFERROR($B15/C$2,"")) -> 4 | D15: =IF(ISBLANK($B15),"",IFERROR($B15/D$2,"")) -> 4 | E15: =IF(ISBLANK($B15),"",IFERROR($B15/E$2,"")) -> 2 | F15: =IF(ISBLANK($B15),"",IFERROR($B15/F$2,"")) -> 1.3109244 | G15: =IF(ISBLANK($B15),"",IFERROR($B15/G$2,"")) -> 1 | H15: =IF(ISBLANK($B15),"",IFERROR($B15/H$2,"")) -> 1.3333333 | I15: =IF(ISBLANK($B15),"",IFERROR($B15/I$2,"")) -> 4 | J15: =IF(ISBLANK($B15),"",IFERROR($B15/J$2,"")) -> 2.6666667 | ... AA15: =IF(ISBLANK($B15),"",IFERROR($B15/AA$2,""))
A16: Deep Heal 💯 | B16: 5 | C16: =IF(ISBLANK($B16),"",IFERROR($B16/C$2,"")) -> 5 | D16: =IF(ISBLANK($B16),"",IFERROR($B16/D$2,"")) -> 5 | E16: =IF(ISBLANK($B16),"",IFERROR($B16/E$2,"")) -> 2.5 | F16: =IF(ISBLANK($B16),"",IFERROR($B16/F$2,"")) -> 1.6386555 | G16: =IF(ISBLANK($B16),"",IFERROR($B16/G$2,"")) -> 1.25 | H16: =IF(ISBLANK($B16),"",IFERROR($B16/H$2,"")) -> 1.6666667 | I16: =IF(ISBLANK($B16),"",IFERROR($B16/I$2,"")) -> 5 | J16: =IF(ISBLANK($B16),"",IFERROR($B16/J$2,"")) -> 3.3333333 | ... AA16: =IF(ISBLANK($B16),"",IFERROR($B16/AA$2,""))
A17: Good Luck 💯 | B17: =2.5 -> 2.5 | C17: =IF(ISBLANK($B17),"",IFERROR($B17/C$2,"")) -> 2.5 | D17: =IF(ISBLANK($B17),"",IFERROR($B17/D$2,"")) -> 2.5 | E17: =IF(ISBLANK($B17),"",IFERROR($B17/E$2,"")) -> 1.25 | F17: =IF(ISBLANK($B17),"",IFERROR($B17/F$2,"")) -> 0.81932773 | G17: =IF(ISBLANK($B17),"",IFERROR($B17/G$2,"")) -> 0.625 | H17: =IF(ISBLANK($B17),"",IFERROR($B17/H$2,"")) -> 0.83333333 | I17: =IF(ISBLANK($B17),"",IFERROR($B17/I$2,"")) -> 2.5 | J17: =IF(ISBLANK($B17),"",IFERROR($B17/J$2,"")) -> 1.6666667 | ... AA17: =IF(ISBLANK($B17),"",IFERROR($B17/AA$2,""))
A18: Autoswing 💯 | B18: 5.5 | C18: =IF(ISBLANK($B18),"",IFERROR($B18/C$2,"")) -> 5.5 | D18: =IF(ISBLANK($B18),"",IFERROR($B18/D$2,"")) -> 5.5 | E18: =IF(ISBLANK($B18),"",IFERROR($B18/E$2,"")) -> 2.75 | F18: =IF(ISBLANK($B18),"",IFERROR($B18/F$2,"")) -> 1.802521 | G18: =IF(ISBLANK($B18),"",IFERROR($B18/G$2,"")) -> 1.375 | H18: =IF(ISBLANK($B18),"",IFERROR($B18/H$2,"")) -> 1.8333333 | I18: =IF(ISBLANK($B18),"",IFERROR($B18/I$2,"")) -> 5.5 | J18: =IF(ISBLANK($B18),"",IFERROR($B18/J$2,"")) -> 3.6666667 | ... AA18: =IF(ISBLANK($B18),"",IFERROR($B18/AA$2,""))
A19: Push | B19: 0.5 | C19: =IF(ISBLANK($B19),"",IFERROR($B19/C$2,"")) -> 0.5 | D19: =IF(ISBLANK($B19),"",IFERROR($B19/D$2,"")) -> 0.5 | E19: =IF(ISBLANK($B19),"",IFERROR($B19/E$2,"")) -> 0.25 | F19: =IF(ISBLANK($B19),"",IFERROR($B19/F$2,"")) -> 0.16386555 | G19: =IF(ISBLANK($B19),"",IFERROR($B19/G$2,"")) -> 0.125 | H19: =IF(ISBLANK($B19),"",IFERROR($B19/H$2,"")) -> 0.16666667 | I19: =IF(ISBLANK($B19),"",IFERROR($B19/I$2,"")) -> 0.5 | J19: =IF(ISBLANK($B19),"",IFERROR($B19/J$2,"")) -> 0.33333333 | ... AA19: =IF(ISBLANK($B19),"",IFERROR($B19/AA$2,""))
A20: Difficult Terrain 💯 | B20: 1 | C20: =IF(ISBLANK($B20),"",IFERROR($B20/C$2,"")) -> 1 | D20: =IF(ISBLANK($B20),"",IFERROR($B20/D$2,"")) -> 1 | E20: =IF(ISBLANK($B20),"",IFERROR($B20/E$2,"")) -> 0.5 | F20: =IF(ISBLANK($B20),"",IFERROR($B20/F$2,"")) -> 0.32773109 | G20: =IF(ISBLANK($B20),"",IFERROR($B20/G$2,"")) -> 0.25 | H20: =IF(ISBLANK($B20),"",IFERROR($B20/H$2,"")) -> 0.33333333 | I20: =IF(ISBLANK($B20),"",IFERROR($B20/I$2,"")) -> 1 | J20: =IF(ISBLANK($B20),"",IFERROR($B20/J$2,"")) -> 0.66666667 | ... AA20: =IF(ISBLANK($B20),"",IFERROR($B20/AA$2,""))
A21: Concession 💯 | B21: =5 / 2 -> 2.5 | C21: =IF(ISBLANK($B21),"",IFERROR($B21/C$2,"")) -> 2.5 | D21: =IF(ISBLANK($B21),"",IFERROR($B21/D$2,"")) -> 2.5 | E21: =IF(ISBLANK($B21),"",IFERROR($B21/E$2,"")) -> 1.25 | F21: =IF(ISBLANK($B21),"",IFERROR($B21/F$2,"")) -> 0.81932773 | G21: =IF(ISBLANK($B21),"",IFERROR($B21/G$2,"")) -> 0.625 | H21: =IF(ISBLANK($B21),"",IFERROR($B21/H$2,"")) -> 0.83333333 | I21: =IF(ISBLANK($B21),"",IFERROR($B21/I$2,"")) -> 2.5 | J21: =IF(ISBLANK($B21),"",IFERROR($B21/J$2,"")) -> 1.6666667 | ... AA21: =IF(ISBLANK($B21),"",IFERROR($B21/AA$2,""))
C22: =IF(ISBLANK($B22),"",IFERROR($B22/C$2,"")) | D22: =IF(ISBLANK($B22),"",IFERROR($B22/D$2,"")) | E22: =IF(ISBLANK($B22),"",IFERROR($B22/E$2,"")) | F22: =IF(ISBLANK($B22),"",IFERROR($B22/F$2,"")) | G22: =IF(ISBLANK($B22),"",IFERROR($B22/G$2,"")) | H22: =IF(ISBLANK($B22),"",IFERROR($B22/H$2,"")) | I22: =IF(ISBLANK($B22),"",IFERROR($B22/I$2,"")) | J22: =IF(ISBLANK($B22),"",IFERROR($B22/J$2,"")) | ... AA22: =IF(ISBLANK($B22),"",IFERROR($B22/AA$2,""))
C23: =IF(ISBLANK($B23),"",IFERROR($B23/C$2,"")) | D23: =IF(ISBLANK($B23),"",IFERROR($B23/D$2,"")) | E23: =IF(ISBLANK($B23),"",IFERROR($B23/E$2,"")) | F23: =IF(ISBLANK($B23),"",IFERROR($B23/F$2,"")) | G23: =IF(ISBLANK($B23),"",IFERROR($B23/G$2,"")) | H23: =IF(ISBLANK($B23),"",IFERROR($B23/H$2,"")) | I23: =IF(ISBLANK($B23),"",IFERROR($B23/I$2,"")) | J23: =IF(ISBLANK($B23),"",IFERROR($B23/J$2,"")) | ... AA23: =IF(ISBLANK($B23),"",IFERROR($B23/AA$2,""))
C24: =IF(ISBLANK($B24),"",IFERROR($B24/C$2,"")) | D24: =IF(ISBLANK($B24),"",IFERROR($B24/D$2,"")) | E24: =IF(ISBLANK($B24),"",IFERROR($B24/E$2,"")) | F24: =IF(ISBLANK($B24),"",IFERROR($B24/F$2,"")) | G24: =IF(ISBLANK($B24),"",IFERROR($B24/G$2,"")) | H24: =IF(ISBLANK($B24),"",IFERROR($B24/H$2,"")) | I24: =IF(ISBLANK($B24),"",IFERROR($B24/I$2,"")) | J24: =IF(ISBLANK($B24),"",IFERROR($B24/J$2,"")) | ... AA24: =IF(ISBLANK($B24),"",IFERROR($B24/AA$2,""))
C25: =IF(ISBLANK($B25),"",IFERROR($B25/C$2,"")) | D25: =IF(ISBLANK($B25),"",IFERROR($B25/D$2,"")) | E25: =IF(ISBLANK($B25),"",IFERROR($B25/E$2,"")) | F25: =IF(ISBLANK($B25),"",IFERROR($B25/F$2,"")) | G25: =IF(ISBLANK($B25),"",IFERROR($B25/G$2,"")) | H25: =IF(ISBLANK($B25),"",IFERROR($B25/H$2,"")) | I25: =IF(ISBLANK($B25),"",IFERROR($B25/I$2,"")) | J25: =IF(ISBLANK($B25),"",IFERROR($B25/J$2,"")) | ... AA25: =IF(ISBLANK($B25),"",IFERROR($B25/AA$2,""))
C26: =IF(ISBLANK($B26),"",IFERROR($B26/C$2,"")) | D26: =IF(ISBLANK($B26),"",IFERROR($B26/D$2,"")) | E26: =IF(ISBLANK($B26),"",IFERROR($B26/E$2,"")) | F26: =IF(ISBLANK($B26),"",IFERROR($B26/F$2,"")) | G26: =IF(ISBLANK($B26),"",IFERROR($B26/G$2,"")) | H26: =IF(ISBLANK($B26),"",IFERROR($B26/H$2,"")) | I26: =IF(ISBLANK($B26),"",IFERROR($B26/I$2,"")) | J26: =IF(ISBLANK($B26),"",IFERROR($B26/J$2,"")) | ... AA26: =IF(ISBLANK($B26),"",IFERROR($B26/AA$2,""))
C27: =IF(ISBLANK($B27),"",IFERROR($B27/C$2,"")) | D27: =IF(ISBLANK($B27),"",IFERROR($B27/D$2,"")) | E27: =IF(ISBLANK($B27),"",IFERROR($B27/E$2,"")) | F27: =IF(ISBLANK($B27),"",IFERROR($B27/F$2,"")) | G27: =IF(ISBLANK($B27),"",IFERROR($B27/G$2,"")) | H27: =IF(ISBLANK($B27),"",IFERROR($B27/H$2,"")) | I27: =IF(ISBLANK($B27),"",IFERROR($B27/I$2,"")) | J27: =IF(ISBLANK($B27),"",IFERROR($B27/J$2,"")) | ... AA27: =IF(ISBLANK($B27),"",IFERROR($B27/AA$2,""))
C28: =IF(ISBLANK($B28),"",IFERROR($B28/C$2,"")) | D28: =IF(ISBLANK($B28),"",IFERROR($B28/D$2,"")) | E28: =IF(ISBLANK($B28),"",IFERROR($B28/E$2,"")) | F28: =IF(ISBLANK($B28),"",IFERROR($B28/F$2,"")) | G28: =IF(ISBLANK($B28),"",IFERROR($B28/G$2,"")) | H28: =IF(ISBLANK($B28),"",IFERROR($B28/H$2,"")) | I28: =IF(ISBLANK($B28),"",IFERROR($B28/I$2,"")) | J28: =IF(ISBLANK($B28),"",IFERROR($B28/J$2,"")) | ... AA28: =IF(ISBLANK($B28),"",IFERROR($B28/AA$2,""))
C29: =IF(ISBLANK($B29),"",IFERROR($B29/C$2,"")) | D29: =IF(ISBLANK($B29),"",IFERROR($B29/D$2,"")) | E29: =IF(ISBLANK($B29),"",IFERROR($B29/E$2,"")) | F29: =IF(ISBLANK($B29),"",IFERROR($B29/F$2,"")) | G29: =IF(ISBLANK($B29),"",IFERROR($B29/G$2,"")) | H29: =IF(ISBLANK($B29),"",IFERROR($B29/H$2,"")) | I29: =IF(ISBLANK($B29),"",IFERROR($B29/I$2,"")) | J29: =IF(ISBLANK($B29),"",IFERROR($B29/J$2,"")) | ... AA29: =IF(ISBLANK($B29),"",IFERROR($B29/AA$2,""))
C30: =IF(ISBLANK($B30),"",IFERROR($B30/C$2,"")) | D30: =IF(ISBLANK($B30),"",IFERROR($B30/D$2,"")) | E30: =IF(ISBLANK($B30),"",IFERROR($B30/E$2,"")) | F30: =IF(ISBLANK($B30),"",IFERROR($B30/F$2,"")) | G30: =IF(ISBLANK($B30),"",IFERROR($B30/G$2,"")) | H30: =IF(ISBLANK($B30),"",IFERROR($B30/H$2,"")) | I30: =IF(ISBLANK($B30),"",IFERROR($B30/I$2,"")) | J30: =IF(ISBLANK($B30),"",IFERROR($B30/J$2,"")) | ... AA30: =IF(ISBLANK($B30),"",IFERROR($B30/AA$2,""))
C31: =IF(ISBLANK($B31),"",IFERROR($B31/C$2,"")) | D31: =IF(ISBLANK($B31),"",IFERROR($B31/D$2,"")) | E31: =IF(ISBLANK($B31),"",IFERROR($B31/E$2,"")) | F31: =IF(ISBLANK($B31),"",IFERROR($B31/F$2,"")) | G31: =IF(ISBLANK($B31),"",IFERROR($B31/G$2,"")) | H31: =IF(ISBLANK($B31),"",IFERROR($B31/H$2,"")) | I31: =IF(ISBLANK($B31),"",IFERROR($B31/I$2,"")) | J31: =IF(ISBLANK($B31),"",IFERROR($B31/J$2,"")) | ... AA31: =IF(ISBLANK($B31),"",IFERROR($B31/AA$2,""))
C32: =IF(ISBLANK($B32),"",IFERROR($B32/C$2,"")) | D32: =IF(ISBLANK($B32),"",IFERROR($B32/D$2,"")) | E32: =IF(ISBLANK($B32),"",IFERROR($B32/E$2,"")) | F32: =IF(ISBLANK($B32),"",IFERROR($B32/F$2,"")) | G32: =IF(ISBLANK($B32),"",IFERROR($B32/G$2,"")) | H32: =IF(ISBLANK($B32),"",IFERROR($B32/H$2,"")) | I32: =IF(ISBLANK($B32),"",IFERROR($B32/I$2,"")) | J32: =IF(ISBLANK($B32),"",IFERROR($B32/J$2,"")) | ... AA32: =IF(ISBLANK($B32),"",IFERROR($B32/AA$2,""))
C33: =IF(ISBLANK($B33),"",IFERROR($B33/C$2,"")) | D33: =IF(ISBLANK($B33),"",IFERROR($B33/D$2,"")) | E33: =IF(ISBLANK($B33),"",IFERROR($B33/E$2,"")) | F33: =IF(ISBLANK($B33),"",IFERROR($B33/F$2,"")) | G33: =IF(ISBLANK($B33),"",IFERROR($B33/G$2,"")) | H33: =IF(ISBLANK($B33),"",IFERROR($B33/H$2,"")) | I33: =IF(ISBLANK($B33),"",IFERROR($B33/I$2,"")) | J33: =IF(ISBLANK($B33),"",IFERROR($B33/J$2,"")) | ... AA33: =IF(ISBLANK($B33),"",IFERROR($B33/AA$2,""))
... C68: =IF(ISBLANK($B68),"",IFERROR($B68/C$2,"")) | D68: =IF(ISBLANK($B68),"",IFERROR($B68/D$2,"")) | E68: =IF(ISBLANK($B68),"",IFERROR($B68/E$2,"")) | F68: =IF(ISBLANK($B68),"",IFERROR($B68/F$2,"")) | G68: =IF(ISBLANK($B68),"",IFERROR($B68/G$2,"")) | H68: =IF(ISBLANK($B68),"",IFERROR($B68/H$2,"")) | I68: =IF(ISBLANK($B68),"",IFERROR($B68/I$2,"")) | J68: =IF(ISBLANK($B68),"",IFERROR($B68/J$2,"")) | ... AA68: =IF(ISBLANK($B68),"",IFERROR($B68/AA$2,""))

Sheet Baseline
A2: # of enemies and players | C2: 4 | E2: Average equal fight, party size of 4
A3: Average hit chance | C3: 0.5 | E3: While most attacks are slightly less likely to hit, Harried counteracts this
A4: Average Health lost per hit | C4: 2.25 | E4: Average weapons deal 2 over soak of equivalent type, +1/4 from hearts sometimes
A5: Health value | C5: =2 / C3 -> 4 | E5: If damage is worth 2, and the average attack misses half the time, confirmed health loss is twice that
A6: Rounds per combat | C6: 5 | E6: We're just deciding this
A9: Enemies killed per round | C9: =C2/C6 -> 0.8
A10: Enemies on Round | B10: 1 | C10: =C2-C9*0.5 -> 3.6 | E10: Assumes that half the time, the party manages to prevent some enemies from taking a round by killing or disabling them
A11: Enemies on Round | B11: 2 | C11: =C10-$C$9 -> 2.8
A12: Enemies on Round | B12: 3 | C12: =C11-$C$9 -> 2
A13: Enemies on Round | B13: 4 | C13: =C12-$C$9 -> 1.2
A14: Enemies on Round | B14: 5 | C14: =C13-$C$9 -> 0.4
A16: Value of character attack damage | C16: =C3*C4*C5 -> 4.5 | E16: Damage per hit * hit chance * Health value
A17: Harried value | C17: 1 | E17: Harried reducing defense against 1 attack to follow, OR alternate defense being ~1 lower
A18: Avg attacks per turn | C18: 1.5 | E18: Attacks per round on average, assuming some moving is required or otherwise loss of efficieny on average
A19: Baseline turn value | C19: =(C16+C17) * C18 -> 8.25
A21: Average # of ECRs per fight | C21: =SUM(C10:C14) -> 10 | E21: Total enemy rounds that get taken in the average fight
A22: Total enemy value per fight | C22: =C21*C19 -> 82.5
A23: Average # of player rounds per fight | C23: =C2*C6 -> 20
A24: Total player value per fight | C24: =C23*C19 -> 165
A26: Enemy value per PC | C26: =C22 / C2 -> 20.625 | E26: Total enemy value / players
A27: Average Cards per day | C27: 10 | E27: Assumes the 'average' player has 5 total Mind+Instinct, or ways of generating cards
A28: Card value | C28: ='THE TABEL'!B5 -> 2 | E28: Health (or equivalent) gained per card usage
A29: Total card value per day | C29: =C27*C28 -> 20
A30: Healing per rest | C30: 3 | E30: Assumes 3 Body, or 2 + misc effect, per player
A32: Value recovered per rest | C32: =C5*C30 + C29 -> 32
A33: Full combat encounters per day | C33: =C32/C26 -> 1.5515152 | E33: Equivalent number of combats the party recovers value for after each rest
A36: Consumables used encounter per player | C36: 0.5
A37: Magic items gained encounter per player | C37: =1/6 -> 0.16666667
A38: Consume value per tier | C38: 3
A39: Magic Item value per tier | C39: 30
A41: Equipment bonus to enemies per tier | C41: =C36*C38+C37*C39 -> 6.5
A43: Value / Gold ratio | C43: =2/3 -> 0.66666667
A44: Gold earned per encounter per tier | C44: =C41*C43 -> 4.3333333

Sheet Suits
A1: Okay so all attacks get buffed by Hearts? Or all red cards?
A2: If it's all red cards, Good Luck is an extra 0.5 damage each, for +1 value, making the mechanic very good.
A3: If it's just hearts, you're kind of trying to high-roll, and you have a couple cards a day that are used for real banger attacks.
B5: Hearts | C5: Clubs | D5: Diamonds | E5: Spades
A6: Tarot Suit(s) | B6: Cups | C6: Wands, Batons, Rods | D6: Coins, Pentacles, Disks | E6: Swords
A7: Season | B7: Spring | C7: Summer | D7: Autumn | E7: Winter
A8: Element (Game) | B8: Brilliant | C8: Fire | D8: Shadow | E8: Frost
A9: Concepts | B9: Power, overwhelming, love Emotions, intuition, creativity Relationships, emotional connections | C9: Stability, safety, optimism Energy, motivation, passion Purpose, spirituality, new ideas | D9: Flexibility, cleverness, contingency Money, work, material goods Careers, finances, professions | E9: Mastery, control, destiny Thoughts, words, actions Communication, decisions, asserting power
A10: Skills (Mostly) | B10: Awareness Presence Persuasion Survival Performance Rapport | C10: Brawl Athletics Resilience Mixology Elementalism Meditation Theurgy | D10: Acrobatics Might Masquerade Streetwise Composure Craft | E10: Archery Melee Stealth Insight Academics Medicine
A11: Fundamental Effect | B11: Extra Successes to damaging attacks
A12: Offensive Mechanics | B12: Taunted Frightened | C12: Crippled Bleeding | D12: Harried Vulnerable Necrotic | E12: Slowed Push Difficult Terrain
A13: Defensive Mechanics | B13: Ward Embolden | C13: Hasted Shift | D13: Bolstered Steady | E13: Turn Order Protected
A14: Social Mechanics

Sheet Skills
A1: Skill | B1: Stock Use? | C1: “Auto Attack”? | D1: Premium Use
A2: Athletics | B2: Fancy movement | D2: Improved movement
A3: Acrobatics | B3: Dodge, some forms of fancy movement | D3: Improved movement
A4: Insight | B4: Reflex, “Suspicion” Defense, Noticing things indirectly
A5: Academics | B5: - | C5: Combat Scanner technique
A6: Arcana | B6: - | C6: - | D6: Arcane magic
A7: Awareness | B7: Noticing things | C7: - | D7: Like a cool search or something
A8: Archery | B8: Weapon attacks | C8: Weapon attacks
A9: Masquerade | B9: Disguising + acting | C9: -
A10: Craft
A11: Meditation
A12: Might
A13: Brawl
A14: Persuasion
A15: Composure
A16: Performance
A17: Presence
A18: Melee
A19: Streetwise
A20: Medicine
A21: Rapport
... A26: Theurgy

Sheet Health
A1: OK so the old system was kind of weird, wounds and stuff are neat but it was too complicated
A2: New idea is to have two tracks, "skin" points and "meat" points (need better named)
A3: All are kinds of Health, though, and when you lose Health you subtract from the Short Health if you have any, before losing Long Health.
A4: When you are out of Short Health, you are Wounded, giving you Disadvantage on all flips, and -2 to Speed, Reflex, and all Defenses)
A5: Enemies for simplicity just have health, and are Wounded at half or lower.
A6: Grazed and Wounded Health?
A7: Shallow Health, Deep Health?
A9: 1 Max Deep HP is worth 4, it's sort of an effective point of healing and it doesn't need to be healed to be effective at first, and you save a card
A10: 1 Max Shallow HP is worth 5, because it's the same thing but it's a bit easier to heal up with end of day healing so it has less of a restraint on your cards
A11: The math on the last one is that it's baseline worth 4, and from the standard of 5 Shallow Health you probably can heal an extra 1 over what you lose because of it
A12: So that means that it's worth an extra 5/4, or 25%, bringing it from 4 to 5
A14: Healing, conversely, is probably worth the inverse amount. Health is worth 4, but if it's Deep Health in addition to being a bit restricted we tack like an extra 1 value on that.

Sheet Equipment
A1: Weapon | B1: Accuracy | C1: Damage | D1: Defense | E1: Range | F1: Tags | G1: Notes
A2: Unarmed | B2: 2 | C2: 2 | D2: 1 | E2: M
A3: Light | B3: 1 | C3: 3 | D3: 1 | E3: M
A4: Heavy | B4: 0 | C4: 4 | D4: 0 | E4: M
A5: Shield | B5: 0 | C5: 2 | D5: 2 | E5: M
A6: [Two-Handed] | B6: 0 | C6: ="+1" -> +1 | D6: 0 | E6: M | F6: Two-Handed | G6: Two-Handed weapons require the use of both hands to wield effectively
A7: [Thrown] | B7: 0 | C7: 0 | D7: - | E7: 3 x [Body] | F7: Thrown | G7: Thrown weapons cannot be used to Parry
A8: Spell | B8: 0 | C8: 2 [Element] | D8: - | E8: M | F8: Spell | G8: For Skills with no auto-attack (such as Arcana)
A11: Masterwork items are 20g / tier, and provide a per-encounter value equal to their Level x 3, same as Techniques
A12: Consumables are 2g / tier, and provide value equal to their Level x 3, but FUCKING EXPLODE once used
A13: This ratio is completely made up and not based on anything aside from intuition
A14: Earlier notes suggest that Level 1-2 Masterwork items are like 300% the value/gold ratio of consumables, but in theory people rotate them out and this kind of balances in practice?
A15: I suspect that the key here is to give people enough Gold that upgrading existing Masterwork items starts becoming a real concern / limiting aspect
A17: Work out how much gold the party should get in terms of loot per encounter
A18: As a benchmark, for Re-purpose Materials to be worth it, the party would need at least 24 Gold of scrappable items per day
A20: Grenades and similar assume a base stat (for damage etc.) of 3-5, based on Level; 1-2 assume 3, 3 assumed 4, 4-5 assumes 5

Sheet Card Cheating
A1: If cards are cheated in for full value:
A2: played \ replaced | B2: 1 | C2: 2 | D2: 3 | E2: 4 | F2: 5 | G2: 6 | H2: 7 | I2: 8 | J2: 9 | K2: 10 | L2: 11 | M2: 12 | N2: 13
A3: 1 | B3: =MAX(0, ABS($A3 - B$2)) -> 0 | C3: =MAX(0, $A3 - C$2) -> 0 | D3: =MAX(0, $A3 - D$2) -> 0 | E3: =MAX(0, $A3 - E$2) -> 0 | F3: =MAX(0, $A3 - F$2) -> 0 | G3: =MAX(0, $A3 - G$2) -> 0 | H3: =MAX(0, $A3 - H$2) -> 0 | I3: =MAX(0, $A3 - I$2) -> 0 | J3: =MAX(0, $A3 - J$2) -> 0 | ... N3: =MAX(0, $A3 - N$2) -> 0 | O3: =AVERAGE(B3:N3) -> 0 | Q3: Average of all cards: | T3: =AVERAGE(O3:O15) -> 2.1538462
A4: 2 | B4: =MAX(0, $A4 - B$2) -> 1 | C4: =MAX(0, $A4 - C$2) -> 0 | D4: =MAX(0, $A4 - D$2) -> 0 | E4: =MAX(0, $A4 - E$2) -> 0 | F4: =MAX(0, $A4 - F$2) -> 0 | G4: =MAX(0, $A4 - G$2) -> 0 | H4: =MAX(0, $A4 - H$2) -> 0 | I4: =MAX(0, $A4 - I$2) -> 0 | ... N4: =MAX(0, $A4 - N$2) -> 0 | O4: =AVERAGE(B4:N4) -> 0.076923077 | Q4: Midpoint lol | T4: =AVERAGE(T3,T5) -> 3.0512821
A5: 3 | B5: =MAX(0, $A5 - B$2) -> 2 | C5: =MAX(0, $A5 - C$2) -> 1 | D5: =MAX(0, $A5 - D$2) -> 0 | E5: =MAX(0, $A5 - E$2) -> 0 | F5: =MAX(0, $A5 - F$2) -> 0 | G5: =MAX(0, $A5 - G$2) -> 0 | H5: =MAX(0, $A5 - H$2) -> 0 | I5: =MAX(0, $A5 - I$2) -> 0 | ... N5: =MAX(0, $A5 - N$2) -> 0 | O5: =AVERAGE(B5:N5) -> 0.23076923 | Q5: Average of top half: | T5: =AVERAGE(O10:O15) -> 3.9487179
A6: 4 | B6: =MAX(0, $A6 - B$2) -> 3 | C6: =MAX(0, $A6 - C$2) -> 2 | D6: =MAX(0, $A6 - D$2) -> 1 | E6: =MAX(0, $A6 - E$2) -> 0 | F6: =MAX(0, $A6 - F$2) -> 0 | G6: =MAX(0, $A6 - G$2) -> 0 | H6: =MAX(0, $A6 - H$2) -> 0 | I6: =MAX(0, $A6 - I$2) -> 0 | ... N6: =MAX(0, $A6 - N$2) -> 0 | O6: =AVERAGE(B6:N6) -> 0.46153846
A7: 5 | B7: =MAX(0, $A7 - B$2) -> 4 | C7: =MAX(0, $A7 - C$2) -> 3 | D7: =MAX(0, $A7 - D$2) -> 2 | E7: =MAX(0, $A7 - E$2) -> 1 | F7: =MAX(0, $A7 - F$2) -> 0 | G7: =MAX(0, $A7 - G$2) -> 0 | H7: =MAX(0, $A7 - H$2) -> 0 | I7: =MAX(0, $A7 - I$2) -> 0 | ... N7: =MAX(0, $A7 - N$2) -> 0 | O7: =AVERAGE(B7:N7) -> 0.76923077 | Q7: Average of bottom half: | T7: =AVERAGE(O3:O9) -> 0.61538462
A8: 6 | B8: =MAX(0, $A8 - B$2) -> 5 | C8: =MAX(0, $A8 - C$2) -> 4 | D8: =MAX(0, $A8 - D$2) -> 3 | E8: =MAX(0, $A8 - E$2) -> 2 | F8: =MAX(0, $A8 - F$2) -> 1 | G8: =MAX(0, $A8 - G$2) -> 0 | H8: =MAX(0, $A8 - H$2) -> 0 | I8: =MAX(0, $A8 - I$2) -> 0 | ... N8: =MAX(0, $A8 - N$2) -> 0 | O8: =AVERAGE(B8:N8) -> 1.1538462
A9: 7 | B9: =MAX(0, $A9 - B$2) -> 6 | C9: =MAX(0, $A9 - C$2) -> 5 | D9: =MAX(0, $A9 - D$2) -> 4 | E9: =MAX(0, $A9 - E$2) -> 3 | F9: =MAX(0, $A9 - F$2) -> 2 | G9: =MAX(0, $A9 - G$2) -> 1 | H9: =MAX(0, $A9 - H$2) -> 0 | I9: =MAX(0, $A9 - I$2) -> 0 | ... N9: =MAX(0, $A9 - N$2) -> 0 | O9: =AVERAGE(B9:N9) -> 1.6153846
A10: 8 | B10: =MAX(0, $A10 - B$2) -> 7 | C10: =MAX(0, $A10 - C$2) -> 6 | D10: =MAX(0, $A10 - D$2) -> 5 | E10: =MAX(0, $A10 - E$2) -> 4 | F10: =MAX(0, $A10 - F$2) -> 3 | G10: =MAX(0, $A10 - G$2) -> 2 | H10: =MAX(0, $A10 - H$2) -> 1 | I10: =MAX(0, $A10 - I$2) -> 0 | ... N10: =MAX(0, $A10 - N$2) -> 0 | O10: =AVERAGE(B10:N10) -> 2.1538462
A11: 9 | B11: =MAX(0, $A11 - B$2) -> 8 | C11: =MAX(0, $A11 - C$2) -> 7 | D11: =MAX(0, $A11 - D$2) -> 6 | E11: =MAX(0, $A11 - E$2) -> 5 | F11: =MAX(0, $A11 - F$2) -> 4 | G11: =MAX(0, $A11 - G$2) -> 3 | H11: =MAX(0, $A11 - H$2) -> 2 | I11: =MAX(0, $A11 - I$2) -> 1 | ... N11: =MAX(0, $A11 - N$2) -> 0 | O11: =AVERAGE(B11:N11) -> 2.7692308
A12: 10 | B12: =MAX(0, $A12 - B$2) -> 9 | C12: =MAX(0, $A12 - C$2) -> 8 | D12: =MAX(0, $A12 - D$2) -> 7 | E12: =MAX(0, $A12 - E$2) -> 6 | F12: =MAX(0, $A12 - F$2) -> 5 | G12: =MAX(0, $A12 - G$2) -> 4 | H12: =MAX(0, $A12 - H$2) -> 3 | I12: =MAX(0, $A12 - I$2) -> 2 | ... N12: =MAX(0, $A12 - N$2) -> 0 | O12: =AVERAGE(B12:N12) -> 3.4615385
A13: 11 | B13: =MAX(0, $A13 - B$2) -> 10 | C13: =MAX(0, $A13 - C$2) -> 9 | D13: =MAX(0, $A13 - D$2) -> 8 | E13: =MAX(0, $A13 - E$2) -> 7 | F13: =MAX(0, $A13 - F$2) -> 6 | G13: =MAX(0, $A13 - G$2) -> 5 | H13: =MAX(0, $A13 - H$2) -> 4 | I13: =MAX(0, $A13 - I$2) -> 3 | ... N13: =MAX(0, $A13 - N$2) -> 0 | O13: =AVERAGE(B13:N13) -> 4.2307692
A14: 12 | B14: =MAX(0, $A14 - B$2) -> 11 | C14: =MAX(0, $A14 - C$2) -> 10 | D14: =MAX(0, $A14 - D$2) -> 9 | E14: =MAX(0, $A14 - E$2) -> 8 | F14: =MAX(0, $A14 - F$2) -> 7 | G14: =MAX(0, $A14 - G$2) -> 6 | H14: =MAX(0, $A14 - H$2) -> 5 | I14: =MAX(0, $A14 - I$2) -> 4 | ... N14: =MAX(0, $A14 - N$2) -> 0 | O14: =AVERAGE(B14:N14) -> 5.0769231
A15: 13 | B15: =MAX(0, $A15 - B$2) -> 12 | C15: =MAX(0, $A15 - C$2) -> 11 | D15: =MAX(0, $A15 - D$2) -> 10 | E15: =MAX(0, $A15 - E$2) -> 9 | F15: =MAX(0, $A15 - F$2) -> 8 | G15: =MAX(0, $A15 - G$2) -> 7 | H15: =MAX(0, $A15 - H$2) -> 6 | I15: =MAX(0, $A15 - I$2) -> 5 | ... N15: =MAX(0, $A15 - N$2) -> 0 | O15: =AVERAGE(B15:N15) -> 6
A17: if cards can be cheated for enemies too
A18: played \ replaced | B18: 1 | C18: 2 | D18: 3 | E18: 4 | F18: 5 | G18: 6 | H18: 7 | I18: 8 | J18: 9 | K18: 10 | L18: 11 | M18: 12 | N18: 13
A19: 1 | B19: =MAX(0, ABS($A19 - B$18)) -> 0 | C19: =MAX(0, ABS($A19 - C$18)) -> 1 | D19: =MAX(0, ABS($A19 - D$18)) -> 2 | E19: =MAX(0, ABS($A19 - E$18)) -> 3 | F19: =MAX(0, ABS($A19 - F$18)) -> 4 | G19: =MAX(0, ABS($A19 - G$18)) -> 5 | H19: =MAX(0, ABS($A19 - H$18)) -> 6 | I19: =MAX(0, ABS($A19 - I$18)) -> 7 | ... N19: =MAX(0, ABS($A19 - N$18)) -> 12 | O19: =AVERAGE(B19:N19) -> 6 | Q19: Average of all cards: | T19: =AVERAGE(O19:O31) -> 4.3076923
A20: 2 | B20: =MAX(0, ABS($A20 - B$18)) -> 1 | C20: =MAX(0, ABS($A20 - C$18)) -> 0 | D20: =MAX(0, ABS($A20 - D$18)) -> 1 | E20: =MAX(0, ABS($A20 - E$18)) -> 2 | F20: =MAX(0, ABS($A20 - F$18)) -> 3 | G20: =MAX(0, ABS($A20 - G$18)) -> 4 | H20: =MAX(0, ABS($A20 - H$18)) -> 5 | I20: =MAX(0, ABS($A20 - I$18)) -> 6 | ... N20: =MAX(0, ABS($A20 - N$18)) -> 11 | O20: =AVERAGE(B20:N20) -> 5.1538462
A21: 3 | B21: =MAX(0, ABS($A21 - B$18)) -> 2 | C21: =MAX(0, ABS($A21 - C$18)) -> 1 | D21: =MAX(0, ABS($A21 - D$18)) -> 0 | E21: =MAX(0, ABS($A21 - E$18)) -> 1 | F21: =MAX(0, ABS($A21 - F$18)) -> 2 | G21: =MAX(0, ABS($A21 - G$18)) -> 3 | H21: =MAX(0, ABS($A21 - H$18)) -> 4 | I21: =MAX(0, ABS($A21 - I$18)) -> 5 | ... N21: =MAX(0, ABS($A21 - N$18)) -> 10 | O21: =AVERAGE(B21:N21) -> 4.4615385 | Q21: Average of top half: | T21: =AVERAGE(O26:O31) -> 4.3974359
A22: 4 | B22: =MAX(0, ABS($A22 - B$18)) -> 3 | C22: =MAX(0, ABS($A22 - C$18)) -> 2 | D22: =MAX(0, ABS($A22 - D$18)) -> 1 | E22: =MAX(0, ABS($A22 - E$18)) -> 0 | F22: =MAX(0, ABS($A22 - F$18)) -> 1 | G22: =MAX(0, ABS($A22 - G$18)) -> 2 | H22: =MAX(0, ABS($A22 - H$18)) -> 3 | I22: =MAX(0, ABS($A22 - I$18)) -> 4 | ... N22: =MAX(0, ABS($A22 - N$18)) -> 9 | O22: =AVERAGE(B22:N22) -> 3.9230769
A23: 5 | B23: =MAX(0, ABS($A23 - B$18)) -> 4 | C23: =MAX(0, ABS($A23 - C$18)) -> 3 | D23: =MAX(0, ABS($A23 - D$18)) -> 2 | E23: =MAX(0, ABS($A23 - E$18)) -> 1 | F23: =MAX(0, ABS($A23 - F$18)) -> 0 | G23: =MAX(0, ABS($A23 - G$18)) -> 1 | H23: =MAX(0, ABS($A23 - H$18)) -> 2 | I23: =MAX(0, ABS($A23 - I$18)) -> 3 | ... N23: =MAX(0, ABS($A23 - N$18)) -> 8 | O23: =AVERAGE(B23:N23) -> 3.5384615 | Q23: Average of bottom half: | T23: =AVERAGE(O19:O25) -> 4.2307692
A24: 6 | B24: =MAX(0, ABS($A24 - B$18)) -> 5 | C24: =MAX(0, ABS($A24 - C$18)) -> 4 | D24: =MAX(0, ABS($A24 - D$18)) -> 3 | E24: =MAX(0, ABS($A24 - E$18)) -> 2 | F24: =MAX(0, ABS($A24 - F$18)) -> 1 | G24: =MAX(0, ABS($A24 - G$18)) -> 0 | H24: =MAX(0, ABS($A24 - H$18)) -> 1 | I24: =MAX(0, ABS($A24 - I$18)) -> 2 | ... N24: =MAX(0, ABS($A24 - N$18)) -> 7 | O24: =AVERAGE(B24:N24) -> 3.3076923
A25: 7 | B25: =MAX(0, ABS($A25 - B$18)) -> 6 | C25: =MAX(0, ABS($A25 - C$18)) -> 5 | D25: =MAX(0, ABS($A25 - D$18)) -> 4 | E25: =MAX(0, ABS($A25 - E$18)) -> 3 | F25: =MAX(0, ABS($A25 - F$18)) -> 2 | G25: =MAX(0, ABS($A25 - G$18)) -> 1 | H25: =MAX(0, ABS($A25 - H$18)) -> 0 | I25: =MAX(0, ABS($A25 - I$18)) -> 1 | ... N25: =MAX(0, ABS($A25 - N$18)) -> 6 | O25: =AVERAGE(B25:N25) -> 3.2307692
A26: 8 | B26: =MAX(0, ABS($A26 - B$18)) -> 7 | C26: =MAX(0, ABS($A26 - C$18)) -> 6 | D26: =MAX(0, ABS($A26 - D$18)) -> 5 | E26: =MAX(0, ABS($A26 - E$18)) -> 4 | F26: =MAX(0, ABS($A26 - F$18)) -> 3 | G26: =MAX(0, ABS($A26 - G$18)) -> 2 | H26: =MAX(0, ABS($A26 - H$18)) -> 1 | I26: =MAX(0, ABS($A26 - I$18)) -> 0 | ... N26: =MAX(0, ABS($A26 - N$18)) -> 5 | O26: =AVERAGE(B26:N26) -> 3.3076923
A27: 9 | B27: =MAX(0, ABS($A27 - B$18)) -> 8 | C27: =MAX(0, ABS($A27 - C$18)) -> 7 | D27: =MAX(0, ABS($A27 - D$18)) -> 6 | E27: =MAX(0, ABS($A27 - E$18)) -> 5 | F27: =MAX(0, ABS($A27 - F$18)) -> 4 | G27: =MAX(0, ABS($A27 - G$18)) -> 3 | H27: =MAX(0, ABS($A27 - H$18)) -> 2 | I27: =MAX(0, ABS($A27 - I$18)) -> 1 | ... N27: =MAX(0, ABS($A27 - N$18)) -> 4 | O27: =AVERAGE(B27:N27) -> 3.5384615
A28: 10 | B28: =MAX(0, ABS($A28 - B$18)) -> 9 | C28: =MAX(0, ABS($A28 - C$18)) -> 8 | D28: =MAX(0, ABS($A28 - D$18)) -> 7 | E28: =MAX(0, ABS($A28 - E$18)) -> 6 | F28: =MAX(0, ABS($A28 - F$18)) -> 5 | G28: =MAX(0, ABS($A28 - G$18)) -> 4 | H28: =MAX(0, ABS($A28 - H$18)) -> 3 | I28: =MAX(0, ABS($A28 - I$18)) -> 2 | ... N28: =MAX(0, ABS($A28 - N$18)) -> 3 | O28: =AVERAGE(B28:N28) -> 3.9230769
A29: 11 | B29: =MAX(0, ABS($A29 - B$18)) -> 10 | C29: =MAX(0, ABS($A29 - C$18)) -> 9 | D29: =MAX(0, ABS($A29 - D$18)) -> 8 | E29: =MAX(0, ABS($A29 - E$18)) -> 7 | F29: =MAX(0, ABS($A29 - F$18)) -> 6 | G29: =MAX(0, ABS($A29 - G$18)) -> 5 | H29: =MAX(0, ABS($A29 - H$18)) -> 4 | I29: =MAX(0, ABS($A29 - I$18)) -> 3 | ... N29: =MAX(0, ABS($A29 - N$18)) -> 2 | O29: =AVERAGE(B29:N29) -> 4.4615385
A30: 12 | B30: =MAX(0, ABS($A30 - B$18)) -> 11 | C30: =MAX(0, ABS($A30 - C$18)) -> 10 | D30: =MAX(0, ABS($A30 - D$18)) -> 9 | E30: =MAX(0, ABS($A30 - E$18)) -> 8 | F30: =MAX(0, ABS($A30 - F$18)) -> 7 | G30: =MAX(0, ABS($A30 - G$18)) -> 6 | H30: =MAX(0, ABS($A30 - H$18)) -> 5 | I30: =MAX(0, ABS($A30 - I$18)) -> 4 | ... N30: =MAX(0, ABS($A30 - N$18)) -> 1 | O30: =AVERAGE(B30:N30) -> 5.1538462
A31: 13 | B31: =MAX(0, ABS($A31 - B$18)) -> 12 | C31: =MAX(0, ABS($A31 - C$18)) -> 11 | D31: =MAX(0, ABS($A31 - D$18)) -> 10 | E31: =MAX(0, ABS($A31 - E$18)) -> 9 | F31: =MAX(0, ABS($A31 - F$18)) -> 8 | G31: =MAX(0, ABS($A31 - G$18)) -> 7 | H31: =MAX(0, ABS($A31 - H$18)) -> 6 | I31: =MAX(0, ABS($A31 - I$18)) -> 5 | ... N31: =MAX(0, ABS($A31 - N$18)) -> 0 | O31: =AVERAGE(B31:N31) -> 6

Sheet Sheet2
A1: Athletics
A2: Acrobatics
A3: Insight
A4: Academics
A5: Arcana
A6: Awareness
A7: Archery
A8: Masquerade
A9: Craft
A10: Meditation
A11: Might
A12: Brawl
... A25: Theurgy
